Workbook

Sheet Raw Data
A1: PO_ID | B1: Supplier | C1: Order_Date | D1: Delivery_Date | E1: Item_Category | F1: Order_Status | G1: Quantity | H1: Unit_Price | I1: Negotiated_Price | J1: Defective_Units | K1: Compliance | L1: Lead_Time_Days | M1: Total_Spend | N1: Defect_Rate_Pct | O1: Savings_Pct | P1: Is_Delivered | Q1: Is_Cancelled | R1: Is_Compliant
A2: PO-00001 | B2: Alpha_Inc | C2: 2023-10-17 | D2: 2023-10-25 | E2: Office Supplies | F2: Cancelled | G2: 1176 | H2: 20.13 | I2: 17.81 | K2: Yes | L2: =IF(D2="","",IF(D2-C2<0,"",D2-C2)) -> 8 | M2: =G2*I2 -> 20944.56 | N2: =IF(J2="","",J2/G2*100) | O2: =(H2-I2)/H2*100 -> 11.525087 | P2: =IF(OR(F2="Delivered",F2="Partially Delivered"),1,0) -> 0 | Q2: =IF(F2="Cancelled",1,0) -> 1 | R2: =IF(K2="Yes",1,0) -> 1
A3: PO-00002 | B3: Delta_Logistics | C3: 2022-04-25 | D3: 2022-05-05 | E3: Office Supplies | F3: Delivered | G3: 1509 | H3: 39.32 | I3: 37.34 | J3: 235 | K3: Yes | L3: =IF(D3="","",IF(D3-C3<0,"",D3-C3)) -> 10 | M3: =G3*I3 -> 56346.06 | N3: =IF(J3="","",J3/G3*100) -> 15.573227 | O3: =(H3-I3)/H3*100 -> 5.0356053 | P3: =IF(OR(F3="Delivered",F3="Partially Delivered"),1,0) -> 1 | Q3: =IF(F3="Cancelled",1,0) -> 0 | R3: =IF(K3="Yes",1,0) -> 1
A4: PO-00003 | B4: Gamma_Co | C4: 2022-01-26 | D4: 2022-02-15 | E4: MRO | F4: Delivered | G4: 910 | H4: 95.51 | I4: 92.26 | J4: 41 | K4: Yes | L4: =IF(D4="","",IF(D4-C4<0,"",D4-C4)) -> 20 | M4: =G4*I4 -> 83956.6 | N4: =IF(J4="","",J4/G4*100) -> 4.5054945 | O4: =(H4-I4)/H4*100 -> 3.402785 | P4: =IF(OR(F4="Delivered",F4="Partially Delivered"),1,0) -> 1 | Q4: =IF(F4="Cancelled",1,0) -> 0 | R4: =IF(K4="Yes",1,0) -> 1
A5: PO-00004 | B5: Beta_Supplies | C5: 2022-10-09 | D5: 2022-10-28 | E5: Packaging | F5: Delivered | G5: 1344 | H5: 99.85 | I5: 95.52 | J5: 112 | K5: Yes | L5: =IF(D5="","",IF(D5-C5<0,"",D5-C5)) -> 19 | M5: =G5*I5 -> 128378.88 | N5: =IF(J5="","",J5/G5*100) -> 8.3333333 | O5: =(H5-I5)/H5*100 -> 4.3365048 | P5: =IF(OR(F5="Delivered",F5="Partially Delivered"),1,0) -> 1 | Q5: =IF(F5="Cancelled",1,0) -> 0 | R5: =IF(K5="Yes",1,0) -> 1
A6: PO-00005 | B6: Delta_Logistics | C6: 2022-09-08 | D6: 2022-09-20 | E6: Raw Materials | F6: Delivered | G6: 1180 | H6: 64.07 | I6: 60.53 | J6: 171 | K6: No | L6: =IF(D6="","",IF(D6-C6<0,"",D6-C6)) -> 12 | M6: =G6*I6 -> 71425.4 | N6: =IF(J6="","",J6/G6*100) -> 14.491525 | O6: =(H6-I6)/H6*100 -> 5.5252068 | P6: =IF(OR(F6="Delivered",F6="Partially Delivered"),1,0) -> 1 | Q6: =IF(F6="Cancelled",1,0) -> 0 | R6: =IF(K6="Yes",1,0) -> 0
A7: PO-00006 | B7: Epsilon_Group | C7: 2022-08-17 | D7: 2022-08-29 | E7: MRO | F7: Delivered | G7: 1145 | H7: 69.21 | I7: 63.57 | J7: 39 | K7: Yes | L7: =IF(D7="","",IF(D7-C7<0,"",D7-C7)) -> 12 | M7: =G7*I7 -> 72787.65 | N7: =IF(J7="","",J7/G7*100) -> 3.4061135 | O7: =(H7-I7)/H7*100 -> 8.1491114 | P7: =IF(OR(F7="Delivered",F7="Partially Delivered"),1,0) -> 1 | Q7: =IF(F7="Cancelled",1,0) -> 0 | R7: =IF(K7="Yes",1,0) -> 1
A8: PO-00007 | B8: Gamma_Co | C8: 2022-05-23 | D8: 2022-06-03 | E8: MRO | F8: Delivered | G8: 1774 | H8: 51.37 | I8: 47.82 | J8: 96 | K8: No | L8: =IF(D8="","",IF(D8-C8<0,"",D8-C8)) -> 11 | M8: =G8*I8 -> 84832.68 | N8: =IF(J8="","",J8/G8*100) -> 5.4114994 | O8: =(H8-I8)/H8*100 -> 6.9106482 | P8: =IF(OR(F8="Delivered",F8="Partially Delivered"),1,0) -> 1 | Q8: =IF(F8="Cancelled",1,0) -> 0 | R8: =IF(K8="Yes",1,0) -> 0
A9: PO-00008 | B9: Alpha_Inc | C9: 2022-04-15 | D9: 2022-04-29 | E9: MRO | F9: Delivered | G9: 1094 | H9: 36.93 | I9: 32.78 | J9: 22 | K9: Yes | L9: =IF(D9="","",IF(D9-C9<0,"",D9-C9)) -> 14 | M9: =G9*I9 -> 35861.32 | N9: =IF(J9="","",J9/G9*100) -> 2.0109689 | O9: =(H9-I9)/H9*100 -> 11.237476 | P9: =IF(OR(F9="Delivered",F9="Partially Delivered"),1,0) -> 1 | Q9: =IF(F9="Cancelled",1,0) -> 0 | R9: =IF(K9="Yes",1,0) -> 1
A10: PO-00009 | B10: Gamma_Co | C10: 2023-11-24 | D10: 2023-11-28 | E10: Raw Materials | F10: Partially Delivered | G10: 1688 | H10: 43.93 | I10: 39.89 | J10: 89 | K10: Yes | L10: =IF(D10="","",IF(D10-C10<0,"",D10-C10)) -> 4 | M10: =G10*I10 -> 67334.32 | N10: =IF(J10="","",J10/G10*100) -> 5.2725118 | O10: =(H10-I10)/H10*100 -> 9.1964489 | P10: =IF(OR(F10="Delivered",F10="Partially Delivered"),1,0) -> 1 | Q10: =IF(F10="Cancelled",1,0) -> 0 | R10: =IF(K10="Yes",1,0) -> 1
A11: PO-00010 | B11: Gamma_Co | C11: 2023-07-13 | D11: 2023-07-25 | E11: Raw Materials | F11: Pending | G11: 171 | H11: 76.87 | I11: 70.2 | J11: 8 | K11: Yes | L11: =IF(D11="","",IF(D11-C11<0,"",D11-C11)) -> 12 | M11: =G11*I11 -> 12004.2 | N11: =IF(J11="","",J11/G11*100) -> 4.6783626 | O11: =(H11-I11)/H11*100 -> 8.6769871 | P11: =IF(OR(F11="Delivered",F11="Partially Delivered"),1,0) -> 0 | Q11: =IF(F11="Cancelled",1,0) -> 0 | R11: =IF(K11="Yes",1,0) -> 1
A12: PO-00011 | B12: Epsilon_Group | C12: 2022-03-31 | D12: 2022-04-15 | E12: Raw Materials | F12: Delivered | G12: 5000 | H12: 78.49 | I12: 73.68 | J12: 18 | K12: Yes | L12: =IF(D12="","",IF(D12-C12<0,"",D12-C12)) -> 15 | M12: =G12*I12 -> 368400 | N12: =IF(J12="","",J12/G12*100) -> 0.36 | O12: =(H12-I12)/H12*100 -> 6.1281692 | P12: =IF(OR(F12="Delivered",F12="Partially Delivered"),1,0) -> 1 | Q12: =IF(F12="Cancelled",1,0) -> 0 | R12: =IF(K12="Yes",1,0) -> 1
A13: PO-00012 | B13: Beta_Supplies | C13: 2023-08-28 | D13: 2023-09-11 | E13: Raw Materials | F13: Delivered | G13: 5000 | H13: 88.96 | I13: 86.58 | J13: 115 | K13: Yes | L13: =IF(D13="","",IF(D13-C13<0,"",D13-C13)) -> 14 | M13: =G13*I13 -> 432900 | N13: =IF(J13="","",J13/G13*100) -> 2.3 | O13: =(H13-I13)/H13*100 -> 2.6753597 | P13: =IF(OR(F13="Delivered",F13="Partially Delivered"),1,0) -> 1 | Q13: =IF(F13="Cancelled",1,0) -> 0 | R13: =IF(K13="Yes",1,0) -> 1
A14: PO-00013 | B14: Beta_Supplies | C14: 2023-03-09 | D14: 2023-03-26 | E14: Electronics | F14: Pending | G14: 5000 | H14: 86.74 | I14: 74.86 | J14: 51 | K14: Yes | L14: =IF(D14="","",IF(D14-C14<0,"",D14-C14)) -> 17 | M14: =G14*I14 -> 374300 | N14: =IF(J14="","",J14/G14*100) -> 1.02 | O14: =(H14-I14)/H14*100 -> 13.696103 | P14: =IF(OR(F14="Delivered",F14="Partially Delivered"),1,0) -> 0 | Q14: =IF(F14="Cancelled",1,0) -> 0 | R14: =IF(K14="Yes",1,0) -> 1
A15: PO-00014 | B15: Beta_Supplies | C15: 2022-02-02 | E15: MRO | F15: Delivered | G15: 5000 | H15: 18.3 | I15: 16.88 | K15: Yes | L15: =IF(D15="","",IF(D15-C15<0,"",D15-C15)) | M15: =G15*I15 -> 84400 | N15: =IF(J15="","",J15/G15*100) | O15: =(H15-I15)/H15*100 -> 7.7595628 | P15: =IF(OR(F15="Delivered",F15="Partially Delivered"),1,0) -> 1 | Q15: =IF(F15="Cancelled",1,0) -> 0 | R15: =IF(K15="Yes",1,0) -> 1
A16: PO-00015 | B16: Delta_Logistics | C16: 2022-01-31 | D16: 2022-02-18 | E16: Electronics | F16: Pending | G16: 5000 | H16: 54.5 | I16: 48.45 | J16: 22 | K16: Yes | L16: =IF(D16="","",IF(D16-C16<0,"",D16-C16)) -> 18 | M16: =G16*I16 -> 242250 | N16: =IF(J16="","",J16/G16*100) -> 0.44 | O16: =(H16-I16)/H16*100 -> 11.100917 | P16: =IF(OR(F16="Delivered",F16="Partially Delivered"),1,0) -> 0 | Q16: =IF(F16="Cancelled",1,0) -> 0 | R16: =IF(K16="Yes",1,0) -> 1
A17: PO-00016 | B17: Beta_Supplies | C17: 2022-04-06 | D17: 2022-04-21 | E17: Packaging | F17: Delivered | G17: 5000 | H17: 15.41 | I17: 15.12 | K17: Yes | L17: =IF(D17="","",IF(D17-C17<0,"",D17-C17)) -> 15 | M17: =G17*I17 -> 75600 | N17: =IF(J17="","",J17/G17*100) | O17: =(H17-I17)/H17*100 -> 1.8818949 | P17: =IF(OR(F17="Delivered",F17="Partially Delivered"),1,0) -> 1 | Q17: =IF(F17="Cancelled",1,0) -> 0 | R17: =IF(K17="Yes",1,0) -> 1
A18: PO-00017 | B18: Delta_Logistics | C18: 2022-08-12 | D18: 2022-08-31 | E18: MRO | F18: Delivered | G18: 1173 | H18: 61.54 | I18: 55.49 | J18: 172 | K18: No | L18: =IF(D18="","",IF(D18-C18<0,"",D18-C18)) -> 19 | M18: =G18*I18 -> 65089.77 | N18: =IF(J18="","",J18/G18*100) -> 14.663257 | O18: =(H18-I18)/H18*100 -> 9.8310042 | P18: =IF(OR(F18="Delivered",F18="Partially Delivered"),1,0) -> 1 | Q18: =IF(F18="Cancelled",1,0) -> 0 | R18: =IF(K18="Yes",1,0) -> 0
A19: PO-00018 | B19: Epsilon_Group | C19: 2022-08-27 | D19: 2022-09-04 | E19: Raw Materials | F19: Delivered | G19: 921 | H19: 51.48 | I19: 50.61 | K19: Yes | L19: =IF(D19="","",IF(D19-C19<0,"",D19-C19)) -> 8 | M19: =G19*I19 -> 46611.81 | N19: =IF(J19="","",J19/G19*100) | O19: =(H19-I19)/H19*100 -> 1.6899767 | P19: =IF(OR(F19="Delivered",F19="Partially Delivered"),1,0) -> 1 | Q19: =IF(F19="Cancelled",1,0) -> 0 | R19: =IF(K19="Yes",1,0) -> 1
A20: PO-00019 | B20: Gamma_Co | C20: 2023-06-02 | D20: 2023-06-05 | E20: Raw Materials | F20: Partially Delivered | G20: 1737 | H20: 97.53 | I20: 87.37 | J20: 79 | K20: Yes | L20: =IF(D20="","",IF(D20-C20<0,"",D20-C20)) -> 3 | M20: =G20*I20 -> 151761.69 | N20: =IF(J20="","",J20/G20*100) -> 4.5480714 | O20: =(H20-I20)/H20*100 -> 10.417307 | P20: =IF(OR(F20="Delivered",F20="Partially Delivered"),1,0) -> 1 | Q20: =IF(F20="Cancelled",1,0) -> 0 | R20: =IF(K20="Yes",1,0) -> 1
A21: PO-00020 | B21: Delta_Logistics | C21: 2023-09-09 | D21: 2023-09-24 | E21: Raw Materials | F21: Delivered | G21: 180 | H21: 45.74 | I21: 38.89 | K21: No | L21: =IF(D21="","",IF(D21-C21<0,"",D21-C21)) -> 15 | M21: =G21*I21 -> 7000.2 | N21: =IF(J21="","",J21/G21*100) | O21: =(H21-I21)/H21*100 -> 14.975951 | P21: =IF(OR(F21="Delivered",F21="Partially Delivered"),1,0) -> 1 | Q21: =IF(F21="Cancelled",1,0) -> 0 | R21: =IF(K21="Yes",1,0) -> 0
A22: PO-00021 | B22: Epsilon_Group | C22: 2022-01-28 | D22: 2022-02-12 | E22: Electronics | F22: Cancelled | G22: 1735 | H22: 20.54 | I22: 19.69 | J22: 49 | K22: Yes | L22: =IF(D22="","",IF(D22-C22<0,"",D22-C22)) -> 15 | M22: =G22*I22 -> 34162.15 | N22: =IF(J22="","",J22/G22*100) -> 2.8242075 | O22: =(H22-I22)/H22*100 -> 4.1382668 | P22: =IF(OR(F22="Delivered",F22="Partially Delivered"),1,0) -> 0 | Q22: =IF(F22="Cancelled",1,0) -> 1 | R22: =IF(K22="Yes",1,0) -> 1
A23: PO-00022 | B23: Delta_Logistics | C23: 2023-07-29 | D23: 2023-08-11 | E23: Raw Materials | F23: Delivered | G23: 1382 | H23: 24.93 | I23: 23.75 | K23: Yes | L23: =IF(D23="","",IF(D23-C23<0,"",D23-C23)) -> 13 | M23: =G23*I23 -> 32822.5 | N23: =IF(J23="","",J23/G23*100) | O23: =(H23-I23)/H23*100 -> 4.7332531 | P23: =IF(OR(F23="Delivered",F23="Partially Delivered"),1,0) -> 1 | Q23: =IF(F23="Cancelled",1,0) -> 0 | R23: =IF(K23="Yes",1,0) -> 1
A24: PO-00023 | B24: Epsilon_Group | C24: 2022-07-23 | D24: 2022-08-08 | E24: MRO | F24: Delivered | G24: 819 | H24: 80.89 | I24: 77.03 | J24: 29 | K24: Yes | L24: =IF(D24="","",IF(D24-C24<0,"",D24-C24)) -> 16 | M24: =G24*I24 -> 63087.57 | N24: =IF(J24="","",J24/G24*100) -> 3.5409035 | O24: =(H24-I24)/H24*100 -> 4.7719125 | P24: =IF(OR(F24="Delivered",F24="Partially Delivered"),1,0) -> 1 | Q24: =IF(F24="Cancelled",1,0) -> 0 | R24: =IF(K24="Yes",1,0) -> 1
A25: PO-00024 | B25: Beta_Supplies | C25: 2023-10-28 | D25: 2023-11-03 | E25: Office Supplies | F25: Partially Delivered | G25: 393 | H25: 72.53 | I25: 66.31 | J25: 42 | K25: No | L25: =IF(D25="","",IF(D25-C25<0,"",D25-C25)) -> 6 | M25: =G25*I25 -> 26059.83 | N25: =IF(J25="","",J25/G25*100) -> 10.687023 | O25: =(H25-I25)/H25*100 -> 8.5757618 | P25: =IF(OR(F25="Delivered",F25="Partially Delivered"),1,0) -> 1 | Q25: =IF(F25="Cancelled",1,0) -> 0 | R25: =IF(K25="Yes",1,0) -> 0
A26: PO-00025 | B26: Beta_Supplies | C26: 2023-12-20 | D26: 2024-01-01 | E26: MRO | F26: Delivered | G26: 1565 | H26: 21.3 | I26: 20.09 | J26: 161 | K26: Yes | L26: =IF(D26="","",IF(D26-C26<0,"",D26-C26)) -> 12 | M26: =G26*I26 -> 31440.85 | N26: =IF(J26="","",J26/G26*100) -> 10.28754 | O26: =(H26-I26)/H26*100 -> 5.6807512 | P26: =IF(OR(F26="Delivered",F26="Partially Delivered"),1,0) -> 1 | Q26: =IF(F26="Cancelled",1,0) -> 0 | R26: =IF(K26="Yes",1,0) -> 1
A27: PO-00026 | B27: Epsilon_Group | C27: 2023-07-13 | D27: 2023-07-24 | E27: Packaging | F27: Delivered | G27: 1487 | H27: 19.15 | I27: 17.24 | K27: Yes | L27: =IF(D27="","",IF(D27-C27<0,"",D27-C27)) -> 11 | M27: =G27*I27 -> 25635.88 | N27: =IF(J27="","",J27/G27*100) | O27: =(H27-I27)/H27*100 -> 9.9738903 | P27: =IF(OR(F27="Delivered",F27="Partially Delivered"),1,0) -> 1 | Q27: =IF(F27="Cancelled",1,0) -> 0 | R27: =IF(K27="Yes",1,0) -> 1
A28: PO-00027 | B28: Alpha_Inc | C28: 2023-03-06 | D28: 2023-03-26 | E28: MRO | F28: Delivered | G28: 855 | H28: 78.2 | I28: 67.16 | J28: 17 | K28: Yes | L28: =IF(D28="","",IF(D28-C28<0,"",D28-C28)) -> 20 | M28: =G28*I28 -> 57421.8 | N28: =IF(J28="","",J28/G28*100) -> 1.9883041 | O28: =(H28-I28)/H28*100 -> 14.117647 | P28: =IF(OR(F28="Delivered",F28="Partially Delivered"),1,0) -> 1 | Q28: =IF(F28="Cancelled",1,0) -> 0 | R28: =IF(K28="Yes",1,0) -> 1
A29: PO-00028 | B29: Epsilon_Group | C29: 2022-08-14 | D29: 2022-08-23 | E29: Raw Materials | F29: Delivered | G29: 435 | H29: 17.13 | I29: 15.84 | J29: 8 | K29: Yes | L29: =IF(D29="","",IF(D29-C29<0,"",D29-C29)) -> 9 | M29: =G29*I29 -> 6890.4 | N29: =IF(J29="","",J29/G29*100) -> 1.8390805 | O29: =(H29-I29)/H29*100 -> 7.530648 | P29: =IF(OR(F29="Delivered",F29="Partially Delivered"),1,0) -> 1 | Q29: =IF(F29="Cancelled",1,0) -> 0 | R29: =IF(K29="Yes",1,0) -> 1
A30: PO-00029 | B30: Delta_Logistics | C30: 2023-04-05 | D30: 2023-04-22 | E30: MRO | F30: Delivered | G30: 1265 | H30: 90.26 | I30: 79.47 | J30: 187 | K30: Yes | L30: =IF(D30="","",IF(D30-C30<0,"",D30-C30)) -> 17 | M30: =G30*I30 -> 100529.55 | N30: =IF(J30="","",J30/G30*100) -> 14.782609 | O30: =(H30-I30)/H30*100 -> 11.954354 | P30: =IF(OR(F30="Delivered",F30="Partially Delivered"),1,0) -> 1 | Q30: =IF(F30="Cancelled",1,0) -> 0 | R30: =IF(K30="Yes",1,0) -> 1
A31: PO-00030 | B31: Epsilon_Group | C31: 2023-08-27 | E31: MRO | F31: Delivered | G31: 1005 | H31: 80.55 | I31: 73.31 | J31: 30 | K31: Yes | L31: =IF(D31="","",IF(D31-C31<0,"",D31-C31)) | M31: =G31*I31 -> 73676.55 | N31: =IF(J31="","",J31/G31*100) -> 2.9850746 | O31: =(H31-I31)/H31*100 -> 8.9882061 | P31: =IF(OR(F31="Delivered",F31="Partially Delivered"),1,0) -> 1 | Q31: =IF(F31="Cancelled",1,0) -> 0 | R31: =IF(K31="Yes",1,0) -> 1
A32: PO-00031 | B32: Gamma_Co | C32: 2022-10-12 | D32: 2022-10-26 | E32: Electronics | F32: Delivered | G32: 326 | H32: 18.1 | I32: 15.92 | K32: No | L32: =IF(D32="","",IF(D32-C32<0,"",D32-C32)) -> 14 | M32: =G32*I32 -> 5189.92 | N32: =IF(J32="","",J32/G32*100) | O32: =(H32-I32)/H32*100 -> 12.044199 | P32: =IF(OR(F32="Delivered",F32="Partially Delivered"),1,0) -> 1 | Q32: =IF(F32="Cancelled",1,0) -> 0 | R32: =IF(K32="Yes",1,0) -> 0
A33: PO-00032 | B33: Alpha_Inc | C33: 2022-01-07 | D33: 2022-01-15 | E33: Office Supplies | F33: Delivered | G33: 1234 | H33: 17.64 | I33: 15.66 | J33: 26 | K33: Yes | L33: =IF(D33="","",IF(D33-C33<0,"",D33-C33)) -> 8 | M33: =G33*I33 -> 19324.44 | N33: =IF(J33="","",J33/G33*100) -> 2.1069692 | O33: =(H33-I33)/H33*100 -> 11.22449 | P33: =IF(OR(F33="Delivered",F33="Partially Delivered"),1,0) -> 1 | Q33: =IF(F33="Cancelled",1,0) -> 0 | R33: =IF(K33="Yes",1,0) -> 1
A34: PO-00033 | B34: Epsilon_Group | C34: 2022-06-13 | D34: 2022-06-29 | E34: MRO | F34: Delivered | G34: 509 | H34: 101.27 | I34: 97.82 | J34: 19 | K34: Yes | L34: =IF(D34="","",IF(D34-C34<0,"",D34-C34)) -> 16 | M34: =G34*I34 -> 49790.38 | N34: =IF(J34="","",J34/G34*100) -> 3.7328094 | O34: =(H34-I34)/H34*100 -> 3.4067345 | P34: =IF(OR(F34="Delivered",F34="Partially Delivered"),1,0) -> 1 | Q34: =IF(F34="Cancelled",1,0) -> 0 | R34: =IF(K34="Yes",1,0) -> 1
A35: PO-00034 | B35: Alpha_Inc | C35: 2023-12-16 | D35: 2023-12-17 | E35: Packaging | F35: Delivered | G35: 1387 | H35: 48.71 | I35: 43.71 | J35: 27 | K35: Yes | L35: =IF(D35="","",IF(D35-C35<0,"",D35-C35)) -> 1 | M35: =G35*I35 -> 60625.77 | N35: =IF(J35="","",J35/G35*100) -> 1.9466474 | O35: =(H35-I35)/H35*100 -> 10.264833 | P35: =IF(OR(F35="Delivered",F35="Partially Delivered"),1,0) -> 1 | Q35: =IF(F35="Cancelled",1,0) -> 0 | R35: =IF(K35="Yes",1,0) -> 1
A36: PO-00035 | B36: Alpha_Inc | C36: 2023-03-09 | D36: 2023-03-17 | E36: MRO | F36: Delivered | G36: 71 | H36: 46.39 | I36: 43.18 | J36: 0 | K36: Yes | L36: =IF(D36="","",IF(D36-C36<0,"",D36-C36)) -> 8 | M36: =G36*I36 -> 3065.78 | N36: =IF(J36="","",J36/G36*100) -> 0 | O36: =(H36-I36)/H36*100 -> 6.9195947 | P36: =IF(OR(F36="Delivered",F36="Partially Delivered"),1,0) -> 1 | Q36: =IF(F36="Cancelled",1,0) -> 0 | R36: =IF(K36="Yes",1,0) -> 1
A37: PO-00036 | B37: Epsilon_Group | C37: 2022-12-15 | D37: 2022-12-23 | E37: Office Supplies | F37: Delivered | G37: 302 | H37: 87.73 | I37: 81.52 | J37: 9 | K37: Yes | L37: =IF(D37="","",IF(D37-C37<0,"",D37-C37)) -> 8 | M37: =G37*I37 -> 24619.04 | N37: =IF(J37="","",J37/G37*100) -> 2.9801325 | O37: =(H37-I37)/H37*100 -> 7.0785364 | P37: =IF(OR(F37="Delivered",F37="Partially Delivered"),1,0) -> 1 | Q37: =IF(F37="Cancelled",1,0) -> 0 | R37: =IF(K37="Yes",1,0) -> 1
A38: PO-00037 | B38: Epsilon_Group | C38: 2022-10-12 | D38: 2022-10-31 | E38: Office Supplies | F38: Pending | G38: 797 | H38: 99.54 | I38: 91.37 | J38: 18 | K38: Yes | L38: =IF(D38="","",IF(D38-C38<0,"",D38-C38)) -> 19 | M38: =G38*I38 -> 72821.89 | N38: =IF(J38="","",J38/G38*100) -> 2.2584693 | O38: =(H38-I38)/H38*100 -> 8.2077557 | P38: =IF(OR(F38="Delivered",F38="Partially Delivered"),1,0) -> 0 | Q38: =IF(F38="Cancelled",1,0) -> 0 | R38: =IF(K38="Yes",1,0) -> 1
A39: PO-00038 | B39: Beta_Supplies | C39: 2022-06-09 | D39: 2022-06-27 | E39: Office Supplies | F39: Pending | G39: 906 | H39: 101.21 | I39: 90.9 | J39: 94 | K39: Yes | L39: =IF(D39="","",IF(D39-C39<0,"",D39-C39)) -> 18 | M39: =G39*I39 -> 82355.4 | N39: =IF(J39="","",J39/G39*100) -> 10.375276 | O39: =(H39-I39)/H39*100 -> 10.18674 | P39: =IF(OR(F39="Delivered",F39="Partially Delivered"),1,0) -> 0 | Q39: =IF(F39="Cancelled",1,0) -> 0 | R39: =IF(K39="Yes",1,0) -> 1
A40: PO-00039 | B40: Epsilon_Group | C40: 2022-08-09 | D40: 2022-08-23 | E40: Office Supplies | F40: Delivered | G40: 1634 | H40: 80.53 | I40: 76.15 | J40: 50 | K40: Yes | L40: =IF(D40="","",IF(D40-C40<0,"",D40-C40)) -> 14 | M40: =G40*I40 -> 124429.1 | N40: =IF(J40="","",J40/G40*100) -> 3.0599755 | O40: =(H40-I40)/H40*100 -> 5.4389668 | P40: =IF(OR(F40="Delivered",F40="Partially Delivered"),1,0) -> 1 | Q40: =IF(F40="Cancelled",1,0) -> 0 | R40: =IF(K40="Yes",1,0) -> 1
...

Sheet Supplier Scorecard
A1: Supplier Risk & Performance Scorecard
A2: Source: Procurement KPI Analysis Dataset (777 POs, 2022-01 to 2024-01). Lead time excludes 1 record with a delivery date preceding its order date (data error).
A4: Supplier | B4: Total POs | C4: Total Spend | D4: Avg Lead Time (days) | E4: Lead Time Std Dev | F4: CV Lead Time (%) | G4: Cancellation Rate (%) | H4: Avg Defect Rate (%) | I4: Compliance Rate (%) | J4: Avg Savings (%) | K4: Delivery Risk | L4: Quality Risk | M4: Impact Score | N4: Risk Score | O4: Risk Category
A5: Alpha_Inc | B5: =COUNTIF('Raw Data'!$B$2:$B$778,A5) -> 141 | C5: =SUMIF('Raw Data'!$B$2:$B$778,A5,'Raw Data'!$M$2:$M$778) -> 7839712.2 | D5: =AVERAGEIF('Raw Data'!$B$2:$B$778,A5,'Raw Data'!$L$2:$L$778) -> 10.741379 | E5: =SQRT(SUMPRODUCT(('Raw Data'!$B$2:$B$778=A5)*('Raw Data'!$L$2:$L$778<>"")*((IF('Raw Data'!$L$2:$L$778="",0,'Raw Data'!$L$2:$L$778)-D5)^2)) / MAX(1,SUMPRODUCT(('Raw Data'!$B$2:$B$778=A5)*('Raw Data'!$L$2:$L$778<>""))-1)) -> 5.4805914 | F5: =IF(D5=0,0,E5/D5*100) -> 51.023162 | G5: =SUMIF('Raw Data'!$B$2:$B$778,A5,'Raw Data'!$Q$2:$Q$778)/B5*100 -> 9.2198582 | H5: =AVERAGEIF('Raw Data'!$B$2:$B$778,A5,'Raw Data'!$N$2:$N$778) -> 2.3590024 | I5: =SUMIF('Raw Data'!$B$2:$B$778,A5,'Raw Data'!$R$2:$R$778)/B5*100 -> 93.617021 | J5: =AVERAGEIF('Raw Data'!$B$2:$B$778,A5,'Raw Data'!$O$2:$O$778) -> 8.210459 | K5: =(( G5-MIN($G$5:$G$9) )/MAX(0.0001,MAX($G$5:$G$9)-MIN($G$5:$G$9)) *0.5 + ( F5-MIN($F$5:$F$9) )/MAX(0.0001,MAX($F$5:$F$9)-MIN($F$5:$F$9)) *0.5) *100 -> 53.93792 | L5: =(( H5-MIN($H$5:$H$9) )/MAX(0.0001,MAX($H$5:$H$9)-MIN($H$5:$H$9)) *0.6 + ( (100-I5)-MIN(100-$I$5:$I$9) )/MAX(0.0001,MAX(100-$I$5:$I$9)-MIN(100-$I$5:$I$9)) *0.4) *100 -> 0 | M5: =( C5-MIN($C$5:$C$9) )/MAX(0.0001,MAX($C$5:$C$9)-MIN($C$5:$C$9)) *100 -> 0 | N5: =K5*0.4+L5*0.3+M5*0.3 -> 21.575168 | O5: =IF(N5>=75,"Critical Risk",IF(N5>=50,"High Risk",IF(N5>=25,"Medium Risk","Low Risk"))) -> Low Risk
A6: Beta_Supplies | B6: =COUNTIF('Raw Data'!$B$2:$B$778,A6) -> 156 | C6: =SUMIF('Raw Data'!$B$2:$B$778,A6,'Raw Data'!$M$2:$M$778) -> 9858665.9 | D6: =AVERAGEIF('Raw Data'!$B$2:$B$778,A6,'Raw Data'!$L$2:$L$778) -> 11.272727 | E6: =SQRT(SUMPRODUCT(('Raw Data'!$B$2:$B$778=A6)*('Raw Data'!$L$2:$L$778<>"")*((IF('Raw Data'!$L$2:$L$778="",0,'Raw Data'!$L$2:$L$778)-D6)^2)) / MAX(1,SUMPRODUCT(('Raw Data'!$B$2:$B$778=A6)*('Raw Data'!$L$2:$L$778<>""))-1)) -> 5.6918298 | F6: =IF(D6=0,0,E6/D6*100) -> 50.492039 | G6: =SUMIF('Raw Data'!$B$2:$B$778,A6,'Raw Data'!$Q$2:$Q$778)/B6*100 -> 8.974359 | H6: =AVERAGEIF('Raw Data'!$B$2:$B$778,A6,'Raw Data'!$N$2:$N$778) -> 9.776386 | I6: =SUMIF('Raw Data'!$B$2:$B$778,A6,'Raw Data'!$R$2:$R$778)/B6*100 -> 75.641026 | J6: =AVERAGEIF('Raw Data'!$B$2:$B$778,A6,'Raw Data'!$O$2:$O$778) -> 7.8276992 | K6: =(( G6-MIN($G$5:$G$9) )/MAX(0.0001,MAX($G$5:$G$9)-MIN($G$5:$G$9)) *0.5 + ( F6-MIN($F$5:$F$9) )/MAX(0.0001,MAX($F$5:$F$9)-MIN($F$5:$F$9)) *0.5) *100 -> 46.295563 | L6: =(( H6-MIN($H$5:$H$9) )/MAX(0.0001,MAX($H$5:$H$9)-MIN($H$5:$H$9)) *0.6 + ( (100-I6)-MIN(100-$I$5:$I$9) )/MAX(0.0001,MAX(100-$I$5:$I$9)-MIN(100-$I$5:$I$9)) *0.4) *100 -> 36.263822 | M6: =( C6-MIN($C$5:$C$9) )/MAX(0.0001,MAX($C$5:$C$9)-MIN($C$5:$C$9)) *100 -> 100 | N6: =K6*0.4+L6*0.3+M6*0.3 -> 59.397372 | O6: =IF(N6>=75,"Critical Risk",IF(N6>=50,"High Risk",IF(N6>=25,"Medium Risk","Low Risk"))) -> High Risk
A7: Delta_Logistics | B7: =COUNTIF('Raw Data'!$B$2:$B$778,A7) -> 171 | C7: =SUMIF('Raw Data'!$B$2:$B$778,A7,'Raw Data'!$M$2:$M$778) -> 9236240.5 | D7: =AVERAGEIF('Raw Data'!$B$2:$B$778,A7,'Raw Data'!$L$2:$L$778) -> 10.854305 | E7: =SQRT(SUMPRODUCT(('Raw Data'!$B$2:$B$778=A7)*('Raw Data'!$L$2:$L$778<>"")*((IF('Raw Data'!$L$2:$L$778="",0,'Raw Data'!$L$2:$L$778)-D7)^2)) / MAX(1,SUMPRODUCT(('Raw Data'!$B$2:$B$778=A7)*('Raw Data'!$L$2:$L$778<>""))-1)) -> 6.0281532 | F7: =IF(D7=0,0,E7/D7*100) -> 55.536982 | G7: =SUMIF('Raw Data'!$B$2:$B$778,A7,'Raw Data'!$Q$2:$Q$778)/B7*100 -> 9.3567251 | H7: =AVERAGEIF('Raw Data'!$B$2:$B$778,A7,'Raw Data'!$N$2:$N$778) -> 14.631372 | I7: =SUMIF('Raw Data'!$B$2:$B$778,A7,'Raw Data'!$R$2:$R$778)/B7*100 -> 60.818713 | J7: =AVERAGEIF('Raw Data'!$B$2:$B$778,A7,'Raw Data'!$O$2:$O$778) -> 7.8119769 | K7: =(( G7-MIN($G$5:$G$9) )/MAX(0.0001,MAX($G$5:$G$9)-MIN($G$5:$G$9)) *0.5 + ( F7-MIN($F$5:$F$9) )/MAX(0.0001,MAX($F$5:$F$9)-MIN($F$5:$F$9)) *0.5) *100 -> 100 | L7: =(( H7-MIN($H$5:$H$9) )/MAX(0.0001,MAX($H$5:$H$9)-MIN($H$5:$H$9)) *0.6 + ( (100-I7)-MIN(100-$I$5:$I$9) )/MAX(0.0001,MAX(100-$I$5:$I$9)-MIN(100-$I$5:$I$9)) *0.4) *100 -> 60 | M7: =( C7-MIN($C$5:$C$9) )/MAX(0.0001,MAX($C$5:$C$9)-MIN($C$5:$C$9)) *100 -> 69.170891 | N7: =K7*0.4+L7*0.3+M7*0.3 -> 78.751267 | O7: =IF(N7>=75,"Critical Risk",IF(N7>=50,"High Risk",IF(N7>=25,"Medium Risk","Low Risk"))) -> Critical Risk
A8: Epsilon_Group | B8: =COUNTIF('Raw Data'!$B$2:$B$778,A8) -> 166 | C8: =SUMIF('Raw Data'!$B$2:$B$778,A8,'Raw Data'!$M$2:$M$778) -> 9851156.1 | D8: =AVERAGEIF('Raw Data'!$B$2:$B$778,A8,'Raw Data'!$L$2:$L$778) -> 10.865772 | E8: =SQRT(SUMPRODUCT(('Raw Data'!$B$2:$B$778=A8)*('Raw Data'!$L$2:$L$778<>"")*((IF('Raw Data'!$L$2:$L$778="",0,'Raw Data'!$L$2:$L$778)-D8)^2)) / MAX(1,SUMPRODUCT(('Raw Data'!$B$2:$B$778=A8)*('Raw Data'!$L$2:$L$778<>""))-1)) -> 5.7465121 | F8: =IF(D8=0,0,E8/D8*100) -> 52.886369 | G8: =SUMIF('Raw Data'!$B$2:$B$778,A8,'Raw Data'!$Q$2:$Q$778)/B8*100 -> 8.4337349 | H8: =AVERAGEIF('Raw Data'!$B$2:$B$778,A8,'Raw Data'!$N$2:$N$778) -> 3.0683733 | I8: =SUMIF('Raw Data'!$B$2:$B$778,A8,'Raw Data'!$R$2:$R$778)/B8*100 -> 98.192771 | J8: =AVERAGEIF('Raw Data'!$B$2:$B$778,A8,'Raw Data'!$O$2:$O$778) -> 8.0405205 | K8: =(( G8-MIN($G$5:$G$9) )/MAX(0.0001,MAX($G$5:$G$9)-MIN($G$5:$G$9)) *0.5 + ( F8-MIN($F$5:$F$9) )/MAX(0.0001,MAX($F$5:$F$9)-MIN($F$5:$F$9)) *0.5) *100 -> 64.787888 | L8: =(( H8-MIN($H$5:$H$9) )/MAX(0.0001,MAX($H$5:$H$9)-MIN($H$5:$H$9)) *0.6 + ( (100-I8)-MIN(100-$I$5:$I$9) )/MAX(0.0001,MAX(100-$I$5:$I$9)-MIN(100-$I$5:$I$9)) *0.4) *100 -> 3.4681364 | M8: =( C8-MIN($C$5:$C$9) )/MAX(0.0001,MAX($C$5:$C$9)-MIN($C$5:$C$9)) *100 -> 99.628033 | N8: =K8*0.4+L8*0.3+M8*0.3 -> 56.844006 | O8: =IF(N8>=75,"Critical Risk",IF(N8>=50,"High Risk",IF(N8>=25,"Medium Risk","Low Risk"))) -> High Risk
A9: Gamma_Co | B9: =COUNTIF('Raw Data'!$B$2:$B$778,A9) -> 143 | C9: =SUMIF('Raw Data'!$B$2:$B$778,A9,'Raw Data'!$M$2:$M$778) -> 8587921.7 | D9: =AVERAGEIF('Raw Data'!$B$2:$B$778,A9,'Raw Data'!$L$2:$L$778) -> 10.192308 | E9: =SQRT(SUMPRODUCT(('Raw Data'!$B$2:$B$778=A9)*('Raw Data'!$L$2:$L$778<>"")*((IF('Raw Data'!$L$2:$L$778="",0,'Raw Data'!$L$2:$L$778)-D9)^2)) / MAX(1,SUMPRODUCT(('Raw Data'!$B$2:$B$778=A9)*('Raw Data'!$L$2:$L$778<>""))-1)) -> 5.4929076 | F9: =IF(D9=0,0,E9/D9*100) -> 53.892678 | G9: =SUMIF('Raw Data'!$B$2:$B$778,A9,'Raw Data'!$Q$2:$Q$778)/B9*100 -> 4.1958042 | H9: =AVERAGEIF('Raw Data'!$B$2:$B$778,A9,'Raw Data'!$N$2:$N$778) -> 5.0245917 | I9: =SUMIF('Raw Data'!$B$2:$B$778,A9,'Raw Data'!$R$2:$R$778)/B9*100 -> 86.013986 | J9: =AVERAGEIF('Raw Data'!$B$2:$B$778,A9,'Raw Data'!$O$2:$O$778) -> 7.9848562 | K9: =(( G9-MIN($G$5:$G$9) )/MAX(0.0001,MAX($G$5:$G$9)-MIN($G$5:$G$9)) *0.5 + ( F9-MIN($F$5:$F$9) )/MAX(0.0001,MAX($F$5:$F$9)-MIN($F$5:$F$9)) *0.5) *100 -> 33.703441 | L9: =(( H9-MIN($H$5:$H$9) )/MAX(0.0001,MAX($H$5:$H$9)-MIN($H$5:$H$9)) *0.6 + ( (100-I9)-MIN(100-$I$5:$I$9) )/MAX(0.0001,MAX(100-$I$5:$I$9)-MIN(100-$I$5:$I$9)) *0.4) *100 -> 13.03215 | M9: =( C9-MIN($C$5:$C$9) )/MAX(0.0001,MAX($C$5:$C$9)-MIN($C$5:$C$9)) *100 -> 37.059269 | N9: =K9*0.4+L9*0.3+M9*0.3 -> 28.508802 | O9: =IF(N9>=75,"Critical Risk",IF(N9>=50,"High Risk",IF(N9>=25,"Medium Risk","Low Risk"))) -> Medium Risk

Sheet Category Breakdown
A1: Spend & Performance by Item Category
A3: Item Category | B3: Total POs | C3: Total Spend | D3: Spend Share (%) | E3: Avg Lead Time (days) | F3: Cancellation Rate (%) | G3: Avg Defect Rate (%) | H3: Compliance Rate (%) | I3: Avg Savings (%)
A4: Electronics | B4: =COUNTIF('Raw Data'!$E$2:$E$778,A4) -> 152 | C4: =SUMIF('Raw Data'!$E$2:$E$778,A4,'Raw Data'!$M$2:$M$778) -> 8642550.6 | D4: =C4/SUM($C$4:$C$8)*100 -> 19.047491 | E4: =AVERAGEIF('Raw Data'!$E$2:$E$778,A4,'Raw Data'!$L$2:$L$778) -> 11.021583 | F4: =SUMIF('Raw Data'!$E$2:$E$778,A4,'Raw Data'!$Q$2:$Q$778)/B4*100 -> 10.526316 | G4: =AVERAGEIF('Raw Data'!$E$2:$E$778,A4,'Raw Data'!$N$2:$N$778) -> 6.8983984 | H4: =SUMIF('Raw Data'!$E$2:$E$778,A4,'Raw Data'!$R$2:$R$778)/B4*100 -> 85.526316 | I4: =AVERAGEIF('Raw Data'!$E$2:$E$778,A4,'Raw Data'!$O$2:$O$778) -> 7.7221242
A5: MRO | B5: =COUNTIF('Raw Data'!$E$2:$E$778,A5) -> 164 | C5: =SUMIF('Raw Data'!$E$2:$E$778,A5,'Raw Data'!$M$2:$M$778) -> 10126609 | D5: =C5/SUM($C$4:$C$8)*100 -> 22.318236 | E5: =AVERAGEIF('Raw Data'!$E$2:$E$778,A5,'Raw Data'!$L$2:$L$778) -> 11.597315 | F5: =SUMIF('Raw Data'!$E$2:$E$778,A5,'Raw Data'!$Q$2:$Q$778)/B5*100 -> 4.8780488 | G5: =AVERAGEIF('Raw Data'!$E$2:$E$778,A5,'Raw Data'!$N$2:$N$778) -> 6.3956036 | H5: =SUMIF('Raw Data'!$E$2:$E$778,A5,'Raw Data'!$R$2:$R$778)/B5*100 -> 82.317073 | I5: =AVERAGEIF('Raw Data'!$E$2:$E$778,A5,'Raw Data'!$O$2:$O$778) -> 8.2110559
A6: Office Supplies | B6: =COUNTIF('Raw Data'!$E$2:$E$778,A6) -> 174 | C6: =SUMIF('Raw Data'!$E$2:$E$778,A6,'Raw Data'!$M$2:$M$778) -> 10007583 | D6: =C6/SUM($C$4:$C$8)*100 -> 22.055913 | E6: =AVERAGEIF('Raw Data'!$E$2:$E$778,A6,'Raw Data'!$L$2:$L$778) -> 10.510067 | F6: =SUMIF('Raw Data'!$E$2:$E$778,A6,'Raw Data'!$Q$2:$Q$778)/B6*100 -> 9.1954023 | G6: =AVERAGEIF('Raw Data'!$E$2:$E$778,A6,'Raw Data'!$N$2:$N$778) -> 7.8326924 | H6: =SUMIF('Raw Data'!$E$2:$E$778,A6,'Raw Data'!$R$2:$R$778)/B6*100 -> 82.758621 | I6: =AVERAGEIF('Raw Data'!$E$2:$E$778,A6,'Raw Data'!$O$2:$O$778) -> 7.6585786
A7: Packaging | B7: =COUNTIF('Raw Data'!$E$2:$E$778,A7) -> 148 | C7: =SUMIF('Raw Data'!$E$2:$E$778,A7,'Raw Data'!$M$2:$M$778) -> 8125712.5 | D7: =C7/SUM($C$4:$C$8)*100 -> 17.908421 | E7: =AVERAGEIF('Raw Data'!$E$2:$E$778,A7,'Raw Data'!$L$2:$L$778) -> 10.407407 | F7: =SUMIF('Raw Data'!$E$2:$E$778,A7,'Raw Data'!$Q$2:$Q$778)/B7*100 -> 8.1081081 | G7: =AVERAGEIF('Raw Data'!$E$2:$E$778,A7,'Raw Data'!$N$2:$N$778) -> 6.2837367 | H7: =SUMIF('Raw Data'!$E$2:$E$778,A7,'Raw Data'!$R$2:$R$778)/B7*100 -> 79.72973 | I7: =AVERAGEIF('Raw Data'!$E$2:$E$778,A7,'Raw Data'!$O$2:$O$778) -> 8.4396988
A8: Raw Materials | B8: =COUNTIF('Raw Data'!$E$2:$E$778,A8) -> 139 | C8: =SUMIF('Raw Data'!$E$2:$E$778,A8,'Raw Data'!$M$2:$M$778) -> 8471241.4 | D8: =C8/SUM($C$4:$C$8)*100 -> 18.669939 | E8: =AVERAGEIF('Raw Data'!$E$2:$E$778,A8,'Raw Data'!$L$2:$L$778) -> 10.34188 | F8: =SUMIF('Raw Data'!$E$2:$E$778,A8,'Raw Data'!$Q$2:$Q$778)/B8*100 -> 7.9136691 | G8: =AVERAGEIF('Raw Data'!$E$2:$E$778,A8,'Raw Data'!$N$2:$N$778) -> 7.5810707 | H8: =SUMIF('Raw Data'!$E$2:$E$778,A8,'Raw Data'!$R$2:$R$778)/B8*100 -> 81.294964 | I8: =AVERAGEIF('Raw Data'!$E$2:$E$778,A8,'Raw Data'!$O$2:$O$778) -> 7.8356874

Sheet Dashboard
A1: Procurement KPI Dashboard
